Workbook
Name ti: #REF!

Sheet Table1
A1: disag | B1: level | C1: Variable | D1: mean | E1: sd | R1: FCIP | S1: TOPCROP | T1: TOPCROP | U1: TOPCROP | V1: TOPCROP | W1: TOPCROP | X1: TOPCROP | Y1: TOPCROP | Z1: TOPCROP | AA1: TOPCROP | AB1: TOPCROP | AC1: TOPCROP | AD1: TOPCROP | AE1: CGRP | AF1: CGRP | AG1: CGRP | AH1: CGRP | AI1: CGRP
A2: FCIP | B2: FCIP | C2: pool_n | D2: 647486 | I2: =_xlfn.CONCAT(A2:C2) -> FCIPFCIPpool_n | J2: =D2 -> 647486 | K2: =TEXT(D2,"0")&" ("&TEXT(E2,"0")&")" -> 647486 (0) | L2: =TEXT(D2,"0.00")&" ("&TEXT(E2,"0.00")&")" -> 647486.00 (0.00) | R2: FCIP | S2: CORN | T2: SOYBEANS | U2: WHEAT | V2: COTTON | W2: SORGHUM | X2: BARLEY | Y2: RICE | Z2: DRY BEANS | AA2: SUNFLOWERS | AB2: PEANUTS | AC2: DRY PEAS | AD2: CANOLA | AE2: Field crops | AF2: Vegetables | AG2: Forages | AH2: Fruits | AI2: Nuts
A3: CGRP | B3: Field Crops | C3: pool_n | D3: 599535 | I3: =_xlfn.CONCAT(A3:C3) -> CGRPField Cropspool_n | J3: =D3 -> 599535 | K3: =TEXT(D3,"0")&" ("&TEXT(E3,"0")&")" -> 599535 (0) | L3: =TEXT(D3,"0.00")&" ("&TEXT(E3,"0.00")&")" -> 599535.00 (0.00)
A4: CGRP | B4: Nuts | C4: pool_n | D4: 802 | I4: =_xlfn.CONCAT(A4:C4) -> CGRPNutspool_n | J4: =D4 -> 802 | K4: =TEXT(D4,"0")&" ("&TEXT(E4,"0")&")" -> 802 (0) | L4: =TEXT(D4,"0.00")&" ("&TEXT(E4,"0.00")&")" -> 802.00 (0.00) | P4: Variable | Q4: Variables | R4: Full sample | S4: =S2 -> CORN | T4: =T2 -> SOYBEANS | U4: =U2 -> WHEAT | V4: =V2 -> COTTON | W4: =W2 -> SORGHUM | X4: =X2 -> BARLEY | Y4: =Y2 -> RICE | Z4: =Z2 -> DRY BEANS | ... AI4: =AI2 -> Nuts
A5: CGRP | B5: Forages | C5: pool_n | D5: 14312 | I5: =_xlfn.CONCAT(A5:C5) -> CGRPForagespool_n | J5: =D5 -> 14312 | K5: =TEXT(D5,"0")&" ("&TEXT(E5,"0")&")" -> 14312 (0) | L5: =TEXT(D5,"0.00")&" ("&TEXT(E5,"0.00")&")" -> 14312.00 (0.00) | Q5: Summary of business outcomes
A6: CGRP | B6: Fruits | C6: pool_n | D6: 1387 | I6: =_xlfn.CONCAT(A6:C6) -> CGRPFruitspool_n | J6: =D6 -> 1387 | K6: =TEXT(D6,"0")&" ("&TEXT(E6,"0")&")" -> 1387 (0) | L6: =TEXT(D6,"0.00")&" ("&TEXT(E6,"0.00")&")" -> 1387.00 (0.00) | P6: coverage_level_percent | Q6: Coverage level (%) | R6: =VLOOKUP(_xlfn.CONCAT(R$1:R$2,$P6),Table1!$I:$L,4,0) -> 0.73 (0.08) | S6: =VLOOKUP(_xlfn.CONCAT(S$1:S$2,$P6),Table1!$I:$L,4,0) -> 0.75 (0.07) | T6: =VLOOKUP(_xlfn.CONCAT(T$1:T$2,$P6),Table1!$I:$L,4,0) -> 0.74 (0.08) | U6: =VLOOKUP(_xlfn.CONCAT(U$1:U$2,$P6),Table1!$I:$L,4,0) -> 0.70 (0.07) | V6: =VLOOKUP(_xlfn.CONCAT(V$1:V$2,$P6),Table1!$I:$L,4,0) -> 0.67 (0.08) | W6: =VLOOKUP(_xlfn.CONCAT(W$1:W$2,$P6),Table1!$I:$L,4,0) -> 0.68 (0.07) | X6: =VLOOKUP(_xlfn.CONCAT(X$1:X$2,$P6),Table1!$I:$L,4,0) -> 0.71 (0.07) | Y6: =VLOOKUP(_xlfn.CONCAT(Y$1:Y$2,$P6),Table1!$I:$L,4,0) -> 0.68 (0.11) | ... AI6: =VLOOKUP(_xlfn.CONCAT(AI$1:AI$2,$P6),Table1!$I:$L,4,0) -> 0.67 (0.08)
A7: CGRP | B7: Vegetables | C7: pool_n | D7: 31450 | I7: =_xlfn.CONCAT(A7:C7) -> CGRPVegetablespool_n | J7: =D7 -> 31450 | K7: =TEXT(D7,"0")&" ("&TEXT(E7,"0")&")" -> 31450 (0) | L7: =TEXT(D7,"0.00")&" ("&TEXT(E7,"0.00")&")" -> 31450.00 (0.00) | P7: insured_acres | Q7: Net insured area (acres) | R7: =VLOOKUP(_xlfn.CONCAT(R$1:R$2,$P7),Table1!$I:$L,3,0) -> 1281 (4308) | S7: =VLOOKUP(_xlfn.CONCAT(S$1:S$2,$P7),Table1!$I:$L,3,0) -> 1532 (4892) | T7: =VLOOKUP(_xlfn.CONCAT(T$1:T$2,$P7),Table1!$I:$L,3,0) -> 1453 (4598) | U7: =VLOOKUP(_xlfn.CONCAT(U$1:U$2,$P7),Table1!$I:$L,3,0) -> 1398 (4966) | V7: =VLOOKUP(_xlfn.CONCAT(V$1:V$2,$P7),Table1!$I:$L,3,0) -> 1130 (3388) | W7: =VLOOKUP(_xlfn.CONCAT(W$1:W$2,$P7),Table1!$I:$L,3,0) -> 714 (1948) | X7: =VLOOKUP(_xlfn.CONCAT(X$1:X$2,$P7),Table1!$I:$L,3,0) -> 671 (1726) | Y7: =VLOOKUP(_xlfn.CONCAT(Y$1:Y$2,$P7),Table1!$I:$L,3,0) -> 935 (1859) | ... AI7: =VLOOKUP(_xlfn.CONCAT(AI$1:AI$2,$P7),Table1!$I:$L,3,0) -> 1580 (2756)
A8: TOPCROP | B8: WHEAT | C8: pool_n | D8: 125861 | I8: =_xlfn.CONCAT(A8:C8) -> TOPCROPWHEATpool_n | J8: =D8 -> 125861 | K8: =TEXT(D8,"0")&" ("&TEXT(E8,"0")&")" -> 125861 (0) | L8: =TEXT(D8,"0.00")&" ("&TEXT(E8,"0.00")&")" -> 125861.00 (0.00) | P8: liability_amt | Q8: Total insured liability ($ 1,000) | R8: =VLOOKUP(_xlfn.CONCAT(R$1:R$2,$P8),Table1!$I:$L,3,0) -> 482 (2134) | S8: =VLOOKUP(_xlfn.CONCAT(S$1:S$2,$P8),Table1!$I:$L,3,0) -> 786 (3152) | T8: =VLOOKUP(_xlfn.CONCAT(T$1:T$2,$P8),Table1!$I:$L,3,0) -> 497 (1834) | U8: =VLOOKUP(_xlfn.CONCAT(U$1:U$2,$P8),Table1!$I:$L,3,0) -> 242 (1054) | V8: =VLOOKUP(_xlfn.CONCAT(V$1:V$2,$P8),Table1!$I:$L,3,0) -> 420 (1417) | W8: =VLOOKUP(_xlfn.CONCAT(W$1:W$2,$P8),Table1!$I:$L,3,0) -> 120 (385) | X8: =VLOOKUP(_xlfn.CONCAT(X$1:X$2,$P8),Table1!$I:$L,3,0) -> 104 (298) | Y8: =VLOOKUP(_xlfn.CONCAT(Y$1:Y$2,$P8),Table1!$I:$L,3,0) -> 642 (1941) | ... AI8: =VLOOKUP(_xlfn.CONCAT(AI$1:AI$2,$P8),Table1!$I:$L,3,0) -> 4694 (10393)
A9: TOPCROP | B9: CANOLA | C9: pool_n | D9: 6699 | I9: =_xlfn.CONCAT(A9:C9) -> TOPCROPCANOLApool_n | J9: =D9 -> 6699 | K9: =TEXT(D9,"0")&" ("&TEXT(E9,"0")&")" -> 6699 (0) | L9: =TEXT(D9,"0.00")&" ("&TEXT(E9,"0.00")&")" -> 6699.00 (0.00) | P9: total_prem | Q9: Total premium paid ($ 1,000) | R9: =VLOOKUP(_xlfn.CONCAT(R$1:R$2,$P9),Table1!$I:$L,4,0) -> 49.09 (211.81) | S9: =VLOOKUP(_xlfn.CONCAT(S$1:S$2,$P9),Table1!$I:$L,4,0) -> 70.18 (281.87) | T9: =VLOOKUP(_xlfn.CONCAT(T$1:T$2,$P9),Table1!$I:$L,4,0) -> 43.73 (164.57) | U9: =VLOOKUP(_xlfn.CONCAT(U$1:U$2,$P9),Table1!$I:$L,4,0) -> 39.36 (173.57) | V9: =VLOOKUP(_xlfn.CONCAT(V$1:V$2,$P9),Table1!$I:$L,4,0) -> 77.48 (340.85) | W9: =VLOOKUP(_xlfn.CONCAT(W$1:W$2,$P9),Table1!$I:$L,4,0) -> 24.85 (82.21) | X9: =VLOOKUP(_xlfn.CONCAT(X$1:X$2,$P9),Table1!$I:$L,4,0) -> 13.67 (40.38) | Y9: =VLOOKUP(_xlfn.CONCAT(Y$1:Y$2,$P9),Table1!$I:$L,4,0) -> 40.44 (115.55) | ... AI9: =VLOOKUP(_xlfn.CONCAT(AI$1:AI$2,$P9),Table1!$I:$L,4,0) -> 190.85 (461.54)
A10: TOPCROP | B10: OTHER | C10: pool_n | D10: 59704 | I10: =_xlfn.CONCAT(A10:C10) -> TOPCROPOTHERpool_n | J10: =D10 -> 59704 | K10: =TEXT(D10,"0")&" ("&TEXT(E10,"0")&")" -> 59704 (0) | L10: =TEXT(D10,"0.00")&" ("&TEXT(E10,"0.00")&")" -> 59704.00 (0.00) | P10: subsidy | Q10: Total premium subsidy paid ($ 1,000) | R10: =VLOOKUP(_xlfn.CONCAT(R$1:R$2,$P10),Table1!$I:$L,4,0) -> 30.36 (142.65) | S10: =VLOOKUP(_xlfn.CONCAT(S$1:S$2,$P10),Table1!$I:$L,4,0) -> 43.07 (190.86) | T10: =VLOOKUP(_xlfn.CONCAT(T$1:T$2,$P10),Table1!$I:$L,4,0) -> 26.96 (109.73) | U10: =VLOOKUP(_xlfn.CONCAT(U$1:U$2,$P10),Table1!$I:$L,4,0) -> 24.27 (110.55) | V10: =VLOOKUP(_xlfn.CONCAT(V$1:V$2,$P10),Table1!$I:$L,4,0) -> 51.22 (245.51) | W10: =VLOOKUP(_xlfn.CONCAT(W$1:W$2,$P10),Table1!$I:$L,4,0) -> 15.73 (55.41) | X10: =VLOOKUP(_xlfn.CONCAT(X$1:X$2,$P10),Table1!$I:$L,4,0) -> 8.33 (26.62) | Y10: =VLOOKUP(_xlfn.CONCAT(Y$1:Y$2,$P10),Table1!$I:$L,4,0) -> 24.96 (70.54) | ... AI10: =VLOOKUP(_xlfn.CONCAT(AI$1:AI$2,$P10),Table1!$I:$L,4,0) -> 109.74 (261.02)
A11: TOPCROP | B11: RICE | C11: pool_n | D11: 9437 | I11: =_xlfn.CONCAT(A11:C11) -> TOPCROPRICEpool_n | J11: =D11 -> 9437 | K11: =TEXT(D11,"0")&" ("&TEXT(E11,"0")&")" -> 9437 (0) | L11: =TEXT(D11,"0.00")&" ("&TEXT(E11,"0.00")&")" -> 9437.00 (0.00) | P11: indem_amt | Q11: Total premium subsidy paid ($ 1,000) | R11: =VLOOKUP(_xlfn.CONCAT(R$1:R$2,$P11),Table1!$I:$L,4,0) -> 41.88 (310.63) | S11: =VLOOKUP(_xlfn.CONCAT(S$1:S$2,$P11),Table1!$I:$L,4,0) -> 55.67 (397.18) | T11: =VLOOKUP(_xlfn.CONCAT(T$1:T$2,$P11),Table1!$I:$L,4,0) -> 27.31 (151.20) | U11: =VLOOKUP(_xlfn.CONCAT(U$1:U$2,$P11),Table1!$I:$L,4,0) -> 36.42 (230.27) | V11: =VLOOKUP(_xlfn.CONCAT(V$1:V$2,$P11),Table1!$I:$L,4,0) -> 101.72 (668.19) | W11: =VLOOKUP(_xlfn.CONCAT(W$1:W$2,$P11),Table1!$I:$L,4,0) -> 24.82 (136.73) | X11: =VLOOKUP(_xlfn.CONCAT(X$1:X$2,$P11),Table1!$I:$L,4,0) -> 12.27 (54.46) | Y11: =VLOOKUP(_xlfn.CONCAT(Y$1:Y$2,$P11),Table1!$I:$L,4,0) -> 74.89 (584.61) | ... AI11: =VLOOKUP(_xlfn.CONCAT(AI$1:AI$2,$P11),Table1!$I:$L,4,0) -> 188.13 (928.37)
A12: TOPCROP | B12: COTTON | C12: pool_n | D12: 31439 | I12: =_xlfn.CONCAT(A12:C12) -> TOPCROPCOTTONpool_n | J12: =D12 -> 31439 | K12: =TEXT(D12,"0")&" ("&TEXT(E12,"0")&")" -> 31439 (0) | L12: =TEXT(D12,"0.00")&" ("&TEXT(E12,"0.00")&")" -> 31439.00 (0.00) | P12: Rate | Q12: Premium per dollar of liability | R12: =VLOOKUP(_xlfn.CONCAT(R$1:R$2,$P12),Table1!$I:$L,4,0) -> 0.14 (0.11) | S12: =VLOOKUP(_xlfn.CONCAT(S$1:S$2,$P12),Table1!$I:$L,4,0) -> 0.11 (0.09) | T12: =VLOOKUP(_xlfn.CONCAT(T$1:T$2,$P12),Table1!$I:$L,4,0) -> 0.11 (0.09) | U12: =VLOOKUP(_xlfn.CONCAT(U$1:U$2,$P12),Table1!$I:$L,4,0) -> 0.16 (0.11) | V12: =VLOOKUP(_xlfn.CONCAT(V$1:V$2,$P12),Table1!$I:$L,4,0) -> 0.19 (0.14) | W12: =VLOOKUP(_xlfn.CONCAT(W$1:W$2,$P12),Table1!$I:$L,4,0) -> 0.23 (0.15) | X12: =VLOOKUP(_xlfn.CONCAT(X$1:X$2,$P12),Table1!$I:$L,4,0) -> 0.16 (0.10) | Y12: =VLOOKUP(_xlfn.CONCAT(Y$1:Y$2,$P12),Table1!$I:$L,4,0) -> 0.08 (0.06) | ... AI12: =VLOOKUP(_xlfn.CONCAT(AI$1:AI$2,$P12),Table1!$I:$L,4,0) -> 0.04 (0.03)
A13: TOPCROP | B13: SUGAR BEETS | C13: pool_n | D13: 1906 | I13: =_xlfn.CONCAT(A13:C13) -> TOPCROPSUGAR BEETSpool_n | J13: =D13 -> 1906 | K13: =TEXT(D13,"0")&" ("&TEXT(E13,"0")&")" -> 1906 (0) | L13: =TEXT(D13,"0.00")&" ("&TEXT(E13,"0.00")&")" -> 1906.00 (0.00) | P13: Suby | Q13: Subsidy per dollar of premium | R13: =VLOOKUP(_xlfn.CONCAT(R$1:R$2,$P13),Table1!$I:$L,4,0) -> 0.61 (0.10) | S13: =VLOOKUP(_xlfn.CONCAT(S$1:S$2,$P13),Table1!$I:$L,4,0) -> 0.61 (0.10) | T13: =VLOOKUP(_xlfn.CONCAT(T$1:T$2,$P13),Table1!$I:$L,4,0) -> 0.61 (0.11) | U13: =VLOOKUP(_xlfn.CONCAT(U$1:U$2,$P13),Table1!$I:$L,4,0) -> 0.61 (0.09) | V13: =VLOOKUP(_xlfn.CONCAT(V$1:V$2,$P13),Table1!$I:$L,4,0) -> 0.64 (0.09) | W13: =VLOOKUP(_xlfn.CONCAT(W$1:W$2,$P13),Table1!$I:$L,4,0) -> 0.62 (0.08) | X13: =VLOOKUP(_xlfn.CONCAT(X$1:X$2,$P13),Table1!$I:$L,4,0) -> 0.60 (0.09) | Y13: =VLOOKUP(_xlfn.CONCAT(Y$1:Y$2,$P13),Table1!$I:$L,4,0) -> 0.60 (0.13) | ... AI13: =VLOOKUP(_xlfn.CONCAT(AI$1:AI$2,$P13),Table1!$I:$L,4,0) -> 0.60 (0.06)
A14: TOPCROP | B14: CORN | C14: pool_n | D14: 133526 | I14: =_xlfn.CONCAT(A14:C14) -> TOPCROPCORNpool_n | J14: =D14 -> 133526 | K14: =TEXT(D14,"0")&" ("&TEXT(E14,"0")&")" -> 133526 (0) | L14: =TEXT(D14,"0.00")&" ("&TEXT(E14,"0.00")&")" -> 133526.00 (0.00) | P14: RateP | Q14: Producer paid premium rate | R14: =VLOOKUP(_xlfn.CONCAT(R$1:R$2,$P14),Table1!$I:$L,4,0) -> 0.05 (0.05) | S14: =VLOOKUP(_xlfn.CONCAT(S$1:S$2,$P14),Table1!$I:$L,4,0) -> 0.05 (0.04) | T14: =VLOOKUP(_xlfn.CONCAT(T$1:T$2,$P14),Table1!$I:$L,4,0) -> 0.05 (0.04) | U14: =VLOOKUP(_xlfn.CONCAT(U$1:U$2,$P14),Table1!$I:$L,4,0) -> 0.06 (0.05) | V14: =VLOOKUP(_xlfn.CONCAT(V$1:V$2,$P14),Table1!$I:$L,4,0) -> 0.07 (0.06) | W14: =VLOOKUP(_xlfn.CONCAT(W$1:W$2,$P14),Table1!$I:$L,4,0) -> 0.09 (0.06) | X14: =VLOOKUP(_xlfn.CONCAT(X$1:X$2,$P14),Table1!$I:$L,4,0) -> 0.06 (0.05) | Y14: =VLOOKUP(_xlfn.CONCAT(Y$1:Y$2,$P14),Table1!$I:$L,4,0) -> 0.03 (0.03) | ... AI14: =VLOOKUP(_xlfn.CONCAT(AI$1:AI$2,$P14),Table1!$I:$L,4,0) -> 0.02 (0.01)
A15: TOPCROP | B15: DRY BEANS | C15: pool_n | D15: 16311 | I15: =_xlfn.CONCAT(A15:C15) -> TOPCROPDRY BEANSpool_n | J15: =D15 -> 16311 | K15: =TEXT(D15,"0")&" ("&TEXT(E15,"0")&")" -> 16311 (0) | L15: =TEXT(D15,"0.00")&" ("&TEXT(E15,"0.00")&")" -> 16311.00 (0.00) | Q15: Actuarial data master outcomes
A16: TOPCROP | B16: SORGHUM | C16: pool_n | D16: 32582 | I16: =_xlfn.CONCAT(A16:C16) -> TOPCROPSORGHUMpool_n | J16: =D16 -> 32582 | K16: =TEXT(D16,"0")&" ("&TEXT(E16,"0")&")" -> 32582 (0) | L16: =TEXT(D16,"0.00")&" ("&TEXT(E16,"0.00")&")" -> 32582.00 (0.00) | P16: Rr | Q16: Reference rate | R16: =VLOOKUP(_xlfn.CONCAT(R$1:R$2,$P16),Table1!$I:$L,4,0) -> 0.03 (0.02) | S16: =VLOOKUP(_xlfn.CONCAT(S$1:S$2,$P16),Table1!$I:$L,4,0) -> 0.03 (0.02) | T16: =VLOOKUP(_xlfn.CONCAT(T$1:T$2,$P16),Table1!$I:$L,4,0) -> 0.02 (0.01) | U16: =VLOOKUP(_xlfn.CONCAT(U$1:U$2,$P16),Table1!$I:$L,4,0) -> 0.03 (0.02) | V16: =VLOOKUP(_xlfn.CONCAT(V$1:V$2,$P16),Table1!$I:$L,4,0) -> 0.03 (0.01) | W16: =VLOOKUP(_xlfn.CONCAT(W$1:W$2,$P16),Table1!$I:$L,4,0) -> 0.04 (0.02) | X16: =VLOOKUP(_xlfn.CONCAT(X$1:X$2,$P16),Table1!$I:$L,4,0) -> 0.03 (0.02) | Y16: =VLOOKUP(_xlfn.CONCAT(Y$1:Y$2,$P16),Table1!$I:$L,4,0) -> 0.02 (0.01) | ... AI16: =VLOOKUP(_xlfn.CONCAT(AI$1:AI$2,$P16),Table1!$I:$L,4,0) -> 0.01 (0.01)
A17: TOPCROP | B17: DRY PEAS | C17: pool_n | D17: 10677 | I17: =_xlfn.CONCAT(A17:C17) -> TOPCROPDRY PEASpool_n | J17: =D17 -> 10677 | K17: =TEXT(D17,"0")&" ("&TEXT(E17,"0")&")" -> 10677 (0) | L17: =TEXT(D17,"0.00")&" ("&TEXT(E17,"0.00")&")" -> 10677.00 (0.00) | P17: Rf | Q17: Fixed rate | R17: =VLOOKUP(_xlfn.CONCAT(R$1:R$2,$P17),Table1!$I:$L,4,0) -> 0.11 (0.09) | S17: =VLOOKUP(_xlfn.CONCAT(S$1:S$2,$P17),Table1!$I:$L,4,0) -> 0.08 (0.07) | T17: =VLOOKUP(_xlfn.CONCAT(T$1:T$2,$P17),Table1!$I:$L,4,0) -> 0.09 (0.08) | U17: =VLOOKUP(_xlfn.CONCAT(U$1:U$2,$P17),Table1!$I:$L,4,0) -> 0.11 (0.08) | V17: =VLOOKUP(_xlfn.CONCAT(V$1:V$2,$P17),Table1!$I:$L,4,0) -> 0.16 (0.12) | W17: =VLOOKUP(_xlfn.CONCAT(W$1:W$2,$P17),Table1!$I:$L,4,0) -> 0.17 (0.12) | X17: =VLOOKUP(_xlfn.CONCAT(X$1:X$2,$P17),Table1!$I:$L,4,0) -> 0.12 (0.08) | Y17: =VLOOKUP(_xlfn.CONCAT(Y$1:Y$2,$P17),Table1!$I:$L,4,0) -> 0.03 (0.02) | ... AI17: =VLOOKUP(_xlfn.CONCAT(AI$1:AI$2,$P17),Table1!$I:$L,4,0) -> 0.04 (0.02)
A18: TOPCROP | B18: SUNFLOWERS | C18: pool_n | D18: 15723 | I18: =_xlfn.CONCAT(A18:C18) -> TOPCROPSUNFLOWERSpool_n | J18: =D18 -> 15723 | K18: =TEXT(D18,"0")&" ("&TEXT(E18,"0")&")" -> 15723 (0) | L18: =TEXT(D18,"0.00")&" ("&TEXT(E18,"0.00")&")" -> 15723.00 (0.00) | P18: Expo | Q18: Rating exponent | R18: =VLOOKUP(_xlfn.CONCAT(R$1:R$2,$P18),Table1!$I:$L,4,0) -> -1.39 (0.57) | S18: =VLOOKUP(_xlfn.CONCAT(S$1:S$2,$P18),Table1!$I:$L,4,0) -> -1.40 (0.57) | T18: =VLOOKUP(_xlfn.CONCAT(T$1:T$2,$P18),Table1!$I:$L,4,0) -> -1.58 (0.44) | U18: =VLOOKUP(_xlfn.CONCAT(U$1:U$2,$P18),Table1!$I:$L,4,0) -> -1.50 (0.49) | V18: =VLOOKUP(_xlfn.CONCAT(V$1:V$2,$P18),Table1!$I:$L,4,0) -> -1.04 (0.37) | W18: =VLOOKUP(_xlfn.CONCAT(W$1:W$2,$P18),Table1!$I:$L,4,0) -> -1.40 (0.58) | X18: =VLOOKUP(_xlfn.CONCAT(X$1:X$2,$P18),Table1!$I:$L,4,0) -> -1.40 (0.50) | Y18: =VLOOKUP(_xlfn.CONCAT(Y$1:Y$2,$P18),Table1!$I:$L,4,0) -> -1.25 (0.63) | ... AI18: =VLOOKUP(_xlfn.CONCAT(AI$1:AI$2,$P18),Table1!$I:$L,4,0) -> -1.03 (0.65)
A19: TOPCROP | B19: SOYBEANS | C19: pool_n | D19: 180433 | I19: =_xlfn.CONCAT(A19:C19) -> TOPCROPSOYBEANSpool_n | J19: =D19 -> 180433 | K19: =TEXT(D19,"0")&" ("&TEXT(E19,"0")&")" -> 180433 (0) | L19: =TEXT(D19,"0.00")&" ("&TEXT(E19,"0.00")&")" -> 180433.00 (0.00) | P19: Rd50 | Q19: Coverage level differential factor @ 50% | R19: =VLOOKUP(_xlfn.CONCAT(R$1:R$2,$P19),Table1!$I:$L,4,0) -> 0.66 (0.11) | S19: =VLOOKUP(_xlfn.CONCAT(S$1:S$2,$P19),Table1!$I:$L,4,0) -> 0.66 (0.11) | T19: =VLOOKUP(_xlfn.CONCAT(T$1:T$2,$P19),Table1!$I:$L,4,0) -> 0.63 (0.11) | U19: =VLOOKUP(_xlfn.CONCAT(U$1:U$2,$P19),Table1!$I:$L,4,0) -> 0.67 (0.11) | V19: =VLOOKUP(_xlfn.CONCAT(V$1:V$2,$P19),Table1!$I:$L,4,0) -> 0.71 (0.12) | W19: =VLOOKUP(_xlfn.CONCAT(W$1:W$2,$P19),Table1!$I:$L,4,0) -> 0.68 (0.12) | X19: =VLOOKUP(_xlfn.CONCAT(X$1:X$2,$P19),Table1!$I:$L,4,0) -> 0.70 (0.11) | Y19: =VLOOKUP(_xlfn.CONCAT(Y$1:Y$2,$P19),Table1!$I:$L,4,0) -> 0.74 (0.10) | ... AI19: =VLOOKUP(_xlfn.CONCAT(AI$1:AI$2,$P19),Table1!$I:$L,4,0) -> 0.50 (0.11)
A20: TOPCROP | B20: BARLEY | C20: pool_n | D20: 23188 | I20: =_xlfn.CONCAT(A20:C20) -> TOPCROPBARLEYpool_n | J20: =D20 -> 23188 | K20: =TEXT(D20,"0")&" ("&TEXT(E20,"0")&")" -> 23188 (0) | L20: =TEXT(D20,"0.00")&" ("&TEXT(E20,"0.00")&")" -> 23188.00 (0.00) | P20: Rd55 | Q20: Coverage level differential factor @ 55% | R20: =VLOOKUP(_xlfn.CONCAT(R$1:R$2,$P20),Table1!$I:$L,4,0) -> 0.77 (0.12) | S20: =VLOOKUP(_xlfn.CONCAT(S$1:S$2,$P20),Table1!$I:$L,4,0) -> 0.76 (0.11) | T20: =VLOOKUP(_xlfn.CONCAT(T$1:T$2,$P20),Table1!$I:$L,4,0) -> 0.73 (0.11) | U20: =VLOOKUP(_xlfn.CONCAT(U$1:U$2,$P20),Table1!$I:$L,4,0) -> 0.77 (0.11) | V20: =VLOOKUP(_xlfn.CONCAT(V$1:V$2,$P20),Table1!$I:$L,4,0) -> 0.80 (0.13) | W20: =VLOOKUP(_xlfn.CONCAT(W$1:W$2,$P20),Table1!$I:$L,4,0) -> 0.77 (0.13) | X20: =VLOOKUP(_xlfn.CONCAT(X$1:X$2,$P20),Table1!$I:$L,4,0) -> 0.79 (0.11) | Y20: =VLOOKUP(_xlfn.CONCAT(Y$1:Y$2,$P20),Table1!$I:$L,4,0) -> 0.83 (0.10) | ... AI20: =VLOOKUP(_xlfn.CONCAT(AI$1:AI$2,$P20),Table1!$I:$L,4,0) -> 0.68 (0.07)
A21: FCIP | B21: FCIP | C21: obs_n | D21: 3778476 | I21: =_xlfn.CONCAT(A21:C21) -> FCIPFCIPobs_n | J21: =D21 -> 3778476 | K21: =TEXT(D21,"0")&" ("&TEXT(E21,"0")&")" -> 3778476 (0) | L21: =TEXT(D21,"0.00")&" ("&TEXT(E21,"0.00")&")" -> 3778476.00 (0.00) | P21: Rd60 | Q21: Coverage level differential factor @ 60% | R21: =VLOOKUP(_xlfn.CONCAT(R$1:R$2,$P21),Table1!$I:$L,4,0) -> 0.85 (0.11) | S21: =VLOOKUP(_xlfn.CONCAT(S$1:S$2,$P21),Table1!$I:$L,4,0) -> 0.85 (0.11) | T21: =VLOOKUP(_xlfn.CONCAT(T$1:T$2,$P21),Table1!$I:$L,4,0) -> 0.83 (0.10) | U21: =VLOOKUP(_xlfn.CONCAT(U$1:U$2,$P21),Table1!$I:$L,4,0) -> 0.86 (0.12) | V21: =VLOOKUP(_xlfn.CONCAT(V$1:V$2,$P21),Table1!$I:$L,4,0) -> 0.87 (0.13) | W21: =VLOOKUP(_xlfn.CONCAT(W$1:W$2,$P21),Table1!$I:$L,4,0) -> 0.85 (0.13) | X21: =VLOOKUP(_xlfn.CONCAT(X$1:X$2,$P21),Table1!$I:$L,4,0) -> 0.87 (0.11) | Y21: =VLOOKUP(_xlfn.CONCAT(Y$1:Y$2,$P21),Table1!$I:$L,4,0) -> 0.89 (0.09) | ... AI21: =VLOOKUP(_xlfn.CONCAT(AI$1:AI$2,$P21),Table1!$I:$L,4,0) -> 0.81 (0.07)
A22: CGRP | B22: Field Crops | C22: obs_n | D22: 3587403 | I22: =_xlfn.CONCAT(A22:C22) -> CGRPField Cropsobs_n | J22: =D22 -> 3587403 | K22: =TEXT(D22,"0")&" ("&TEXT(E22,"0")&")" -> 3587403 (0) | L22: =TEXT(D22,"0.00")&" ("&TEXT(E22,"0.00")&")" -> 3587403.00 (0.00) | P22: Rd65 | Q22: Coverage level differential factor @ 65% | R22: =VLOOKUP(_xlfn.CONCAT(R$1:R$2,$P22),Table1!$I:$L,4,0) -> 0.95 (0.11) | S22: =VLOOKUP(_xlfn.CONCAT(S$1:S$2,$P22),Table1!$I:$L,4,0) -> 0.95 (0.11) | T22: =VLOOKUP(_xlfn.CONCAT(T$1:T$2,$P22),Table1!$I:$L,4,0) -> 0.96 (0.11) | U22: =VLOOKUP(_xlfn.CONCAT(U$1:U$2,$P22),Table1!$I:$L,4,0) -> 0.95 (0.12) | V22: =VLOOKUP(_xlfn.CONCAT(V$1:V$2,$P22),Table1!$I:$L,4,0) -> 0.95 (0.12) | W22: =VLOOKUP(_xlfn.CONCAT(W$1:W$2,$P22),Table1!$I:$L,4,0) -> 0.94 (0.14) | X22: =VLOOKUP(_xlfn.CONCAT(X$1:X$2,$P22),Table1!$I:$L,4,0) -> 0.96 (0.11) | Y22: =VLOOKUP(_xlfn.CONCAT(Y$1:Y$2,$P22),Table1!$I:$L,4,0) -> 0.97 (0.08) | ... AI22: =VLOOKUP(_xlfn.CONCAT(AI$1:AI$2,$P22),Table1!$I:$L,4,0) -> 0.98 (0.08)
A23: CGRP | B23: Nuts | C23: obs_n | D23: 7020 | I23: =_xlfn.CONCAT(A23:C23) -> CGRPNutsobs_n | J23: =D23 -> 7020 | K23: =TEXT(D23,"0")&" ("&TEXT(E23,"0")&")" -> 7020 (0) | L23: =TEXT(D23,"0.00")&" ("&TEXT(E23,"0.00")&")" -> 7020.00 (0.00) | P23: Rd70 | Q23: Coverage level differential factor @ 70% | R23: =VLOOKUP(_xlfn.CONCAT(R$1:R$2,$P23),Table1!$I:$L,4,0) -> 1.08 (0.12) | S23: =VLOOKUP(_xlfn.CONCAT(S$1:S$2,$P23),Table1!$I:$L,4,0) -> 1.08 (0.11) | T23: =VLOOKUP(_xlfn.CONCAT(T$1:T$2,$P23),Table1!$I:$L,4,0) -> 1.11 (0.13) | U23: =VLOOKUP(_xlfn.CONCAT(U$1:U$2,$P23),Table1!$I:$L,4,0) -> 1.06 (0.11) | V23: =VLOOKUP(_xlfn.CONCAT(V$1:V$2,$P23),Table1!$I:$L,4,0) -> 1.05 (0.11) | W23: =VLOOKUP(_xlfn.CONCAT(W$1:W$2,$P23),Table1!$I:$L,4,0) -> 1.04 (0.12) | X23: =VLOOKUP(_xlfn.CONCAT(X$1:X$2,$P23),Table1!$I:$L,4,0) -> 1.06 (0.10) | Y23: =VLOOKUP(_xlfn.CONCAT(Y$1:Y$2,$P23),Table1!$I:$L,4,0) -> 1.07 (0.09) | ... AI23: =VLOOKUP(_xlfn.CONCAT(AI$1:AI$2,$P23),Table1!$I:$L,4,0) -> 1.19 (0.10)
A24: CGRP | B24: Forages | C24: obs_n | D24: 56199 | I24: =_xlfn.CONCAT(A24:C24) -> CGRPForagesobs_n | J24: =D24 -> 56199 | K24: =TEXT(D24,"0")&" ("&TEXT(E24,"0")&")" -> 56199 (0) | L24: =TEXT(D24,"0.00")&" ("&TEXT(E24,"0.00")&")" -> 56199.00 (0.00) | P24: Rd75 | Q24: Coverage level differential factor @ 75% | R24: =VLOOKUP(_xlfn.CONCAT(R$1:R$2,$P24),Table1!$I:$L,4,0) -> 1.22 (0.14) | S24: =VLOOKUP(_xlfn.CONCAT(S$1:S$2,$P24),Table1!$I:$L,4,0) -> 1.22 (0.13) | T24: =VLOOKUP(_xlfn.CONCAT(T$1:T$2,$P24),Table1!$I:$L,4,0) -> 1.30 (0.17) | U24: =VLOOKUP(_xlfn.CONCAT(U$1:U$2,$P24),Table1!$I:$L,4,0) -> 1.18 (0.12) | V24: =VLOOKUP(_xlfn.CONCAT(V$1:V$2,$P24),Table1!$I:$L,4,0) -> 1.16 (0.10) | W24: =VLOOKUP(_xlfn.CONCAT(W$1:W$2,$P24),Table1!$I:$L,4,0) -> 1.17 (0.11) | X24: =VLOOKUP(_xlfn.CONCAT(X$1:X$2,$P24),Table1!$I:$L,4,0) -> 1.18 (0.09) | Y24: =VLOOKUP(_xlfn.CONCAT(Y$1:Y$2,$P24),Table1!$I:$L,4,0) -> 1.19 (0.12) | ... AI24: =VLOOKUP(_xlfn.CONCAT(AI$1:AI$2,$P24),Table1!$I:$L,4,0) -> 1.45 (0.13)
A25: CGRP | B25: Fruits | C25: obs_n | D25: 8747 | I25: =_xlfn.CONCAT(A25:C25) -> CGRPFruitsobs_n | J25: =D25 -> 8747 | K25: =TEXT(D25,"0")&" ("&TEXT(E25,"0")&")" -> 8747 (0) | L25: =TEXT(D25,"0.00")&" ("&TEXT(E25,"0.00")&")" -> 8747.00 (0.00) | P25: Rd80 | Q25: Coverage level differential factor @ 80% | R25: =VLOOKUP(_xlfn.CONCAT(R$1:R$2,$P25),Table1!$I:$L,4,0) -> 1.38 (0.20) | S25: =VLOOKUP(_xlfn.CONCAT(S$1:S$2,$P25),Table1!$I:$L,4,0) -> 1.37 (0.16) | T25: =VLOOKUP(_xlfn.CONCAT(T$1:T$2,$P25),Table1!$I:$L,4,0) -> 1.53 (0.23) | U25: =VLOOKUP(_xlfn.CONCAT(U$1:U$2,$P25),Table1!$I:$L,4,0) -> 1.32 (0.14) | V25: =VLOOKUP(_xlfn.CONCAT(V$1:V$2,$P25),Table1!$I:$L,4,0) -> 1.29 (0.12) | W25: =VLOOKUP(_xlfn.CONCAT(W$1:W$2,$P25),Table1!$I:$L,4,0) -> 1.33 (0.12) | X25: =VLOOKUP(_xlfn.CONCAT(X$1:X$2,$P25),Table1!$I:$L,4,0) -> 1.32 (0.10) | Y25: =VLOOKUP(_xlfn.CONCAT(Y$1:Y$2,$P25),Table1!$I:$L,4,0) -> 1.34 (0.17) | ... AI25: =VLOOKUP(_xlfn.CONCAT(AI$1:AI$2,$P25),Table1!$I:$L,4,0) -> 1.71 (0.16)
A26: CGRP | B26: Vegetables | C26: obs_n | D26: 119107 | I26: =_xlfn.CONCAT(A26:C26) -> CGRPVegetablesobs_n | J26: =D26 -> 119107 | K26: =TEXT(D26,"0")&" ("&TEXT(E26,"0")&")" -> 119107 (0) | L26: =TEXT(D26,"0.00")&" ("&TEXT(E26,"0.00")&")" -> 119107.00 (0.00) | P26: Rd85 | Q26: Coverage level differential factor @ 85% | R26: =VLOOKUP(_xlfn.CONCAT(R$1:R$2,$P26),Table1!$I:$L,4,0) -> 1.56 (0.28) | S26: =VLOOKUP(_xlfn.CONCAT(S$1:S$2,$P26),Table1!$I:$L,4,0) -> 1.55 (0.22) | T26: =VLOOKUP(_xlfn.CONCAT(T$1:T$2,$P26),Table1!$I:$L,4,0) -> 1.79 (0.32) | U26: =VLOOKUP(_xlfn.CONCAT(U$1:U$2,$P26),Table1!$I:$L,4,0) -> 1.46 (0.19) | V26: =VLOOKUP(_xlfn.CONCAT(V$1:V$2,$P26),Table1!$I:$L,4,0) -> 1.44 (0.18) | W26: =VLOOKUP(_xlfn.CONCAT(W$1:W$2,$P26),Table1!$I:$L,4,0) -> 1.50 (0.17) | X26: =VLOOKUP(_xlfn.CONCAT(X$1:X$2,$P26),Table1!$I:$L,4,0) -> 1.47 (0.14) | Y26: =VLOOKUP(_xlfn.CONCAT(Y$1:Y$2,$P26),Table1!$I:$L,4,0) -> 1.52 (0.24) | ... AI26: =VLOOKUP(_xlfn.CONCAT(AI$1:AI$2,$P26),Table1!$I:$L,4,0) -> 2.00 (0.21)
A27: TOPCROP | B27: WHEAT | C27: obs_n | D27: 700261 | I27: =_xlfn.CONCAT(A27:C27) -> TOPCROPWHEATobs_n | J27: =D27 -> 700261 | K27: =TEXT(D27,"0")&" ("&TEXT(E27,"0")&")" -> 700261 (0) | L27: =TEXT(D27,"0.00")&" ("&TEXT(E27,"0.00")&")" -> 700261.00 (0.00) | P27: Fu_BU | Q27: Basic unit differential factor | R27: =VLOOKUP(_xlfn.CONCAT(R$1:R$2,$P27),Table1!$I:$L,4,0) -> 1.03 (0.03) | S27: =VLOOKUP(_xlfn.CONCAT(S$1:S$2,$P27),Table1!$I:$L,4,0) -> 1.03 (0.03) | T27: =VLOOKUP(_xlfn.CONCAT(T$1:T$2,$P27),Table1!$I:$L,4,0) -> 1.03 (0.03) | U27: =VLOOKUP(_xlfn.CONCAT(U$1:U$2,$P27),Table1!$I:$L,4,0) -> 1.04 (0.02) | V27: =VLOOKUP(_xlfn.CONCAT(V$1:V$2,$P27),Table1!$I:$L,4,0) -> 1.05 (0.02) | W27: =VLOOKUP(_xlfn.CONCAT(W$1:W$2,$P27),Table1!$I:$L,4,0) -> 1.03 (0.02) | X27: =VLOOKUP(_xlfn.CONCAT(X$1:X$2,$P27),Table1!$I:$L,4,0) -> 1.05 (0.02) | Y27: =VLOOKUP(_xlfn.CONCAT(Y$1:Y$2,$P27),Table1!$I:$L,4,0) -> 1.04 (0.02) | ... AI27: =VLOOKUP(_xlfn.CONCAT(AI$1:AI$2,$P27),Table1!$I:$L,4,0) -> 1.03 (0.02)
A28: TOPCROP | B28: CANOLA | C28: obs_n | D28: 22733 | I28: =_xlfn.CONCAT(A28:C28) -> TOPCROPCANOLAobs_n | J28: =D28 -> 22733 | K28: =TEXT(D28,"0")&" ("&TEXT(E28,"0")&")" -> 22733 (0) | L28: =TEXT(D28,"0.00")&" ("&TEXT(E28,"0.00")&")" -> 22733.00 (0.00) | P28: Fu_EU | Q28: Enterprise unit differential factor | R28: =VLOOKUP(_xlfn.CONCAT(R$1:R$2,$P28),Table1!$I:$L,4,0) -> 1.01 (0.03) | S28: =VLOOKUP(_xlfn.CONCAT(S$1:S$2,$P28),Table1!$I:$L,4,0) -> 1.00 (0.04) | T28: =VLOOKUP(_xlfn.CONCAT(T$1:T$2,$P28),Table1!$I:$L,4,0) -> 0.99 (0.04) | U28: =VLOOKUP(_xlfn.CONCAT(U$1:U$2,$P28),Table1!$I:$L,4,0) -> 1.02 (0.01) | V28: =VLOOKUP(_xlfn.CONCAT(V$1:V$2,$P28),Table1!$I:$L,4,0) -> 1.03 (0.01) | W28: =VLOOKUP(_xlfn.CONCAT(W$1:W$2,$P28),Table1!$I:$L,4,0) -> 1.01 (0.01) | X28: =VLOOKUP(_xlfn.CONCAT(X$1:X$2,$P28),Table1!$I:$L,4,0) -> 1.03 (0.01) | Y28: =VLOOKUP(_xlfn.CONCAT(Y$1:Y$2,$P28),Table1!$I:$L,4,0) -> 1.02 (0.01) | ... AI28: =VLOOKUP(_xlfn.CONCAT(AI$1:AI$2,$P28),Table1!$I:$L,4,0) -> 1.00 (0.01)
A29: TOPCROP | B29: OTHER | C29: obs_n | D29: 285195 | I29: =_xlfn.CONCAT(A29:C29) -> TOPCROPOTHERobs_n | J29: =D29 -> 285195 | K29: =TEXT(D29,"0")&" ("&TEXT(E29,"0")&")" -> 285195 (0) | L29: =TEXT(D29,"0.00")&" ("&TEXT(E29,"0.00")&")" -> 285195.00 (0.00) | P29: pool_n | Q29: Number of insurance pools | R29: =VLOOKUP(_xlfn.CONCAT(R$1:R$2,$P29),Table1!$I:$L,2,0) -> 647486 | S29: =VLOOKUP(_xlfn.CONCAT(S$1:S$2,$P29),Table1!$I:$L,2,0) -> 133526 | T29: =VLOOKUP(_xlfn.CONCAT(T$1:T$2,$P29),Table1!$I:$L,2,0) -> 180433 | U29: =VLOOKUP(_xlfn.CONCAT(U$1:U$2,$P29),Table1!$I:$L,2,0) -> 125861 | V29: =VLOOKUP(_xlfn.CONCAT(V$1:V$2,$P29),Table1!$I:$L,2,0) -> 31439 | W29: =VLOOKUP(_xlfn.CONCAT(W$1:W$2,$P29),Table1!$I:$L,2,0) -> 32582 | X29: =VLOOKUP(_xlfn.CONCAT(X$1:X$2,$P29),Table1!$I:$L,2,0) -> 23188 | Y29: =VLOOKUP(_xlfn.CONCAT(Y$1:Y$2,$P29),Table1!$I:$L,2,0) -> 9437 | ... AI29: =VLOOKUP(_xlfn.CONCAT(AI$1:AI$2,$P29),Table1!$I:$L,2,0) -> 802
A30: TOPCROP | B30: RICE | C30: obs_n | D30: 43075 | I30: =_xlfn.CONCAT(A30:C30) -> TOPCROPRICEobs_n | J30: =D30 -> 43075 | K30: =TEXT(D30,"0")&" ("&TEXT(E30,"0")&")" -> 43075 (0) | L30: =TEXT(D30,"0.00")&" ("&TEXT(E30,"0.00")&")" -> 43075.00 (0.00) | P30: obs_n | Q30: Number of observations | R30: =VLOOKUP(_xlfn.CONCAT(R$1:R$2,$P30),Table1!$I:$L,2,0) -> 3778476 | S30: =VLOOKUP(_xlfn.CONCAT(S$1:S$2,$P30),Table1!$I:$L,2,0) -> 1075064 | T30: =VLOOKUP(_xlfn.CONCAT(T$1:T$2,$P30),Table1!$I:$L,2,0) -> 1017542 | U30: =VLOOKUP(_xlfn.CONCAT(U$1:U$2,$P30),Table1!$I:$L,2,0) -> 700261 | V30: =VLOOKUP(_xlfn.CONCAT(V$1:V$2,$P30),Table1!$I:$L,2,0) -> 211012 | W30: =VLOOKUP(_xlfn.CONCAT(W$1:W$2,$P30),Table1!$I:$L,2,0) -> 167232 | X30: =VLOOKUP(_xlfn.CONCAT(X$1:X$2,$P30),Table1!$I:$L,2,0) -> 86579 | Y30: =VLOOKUP(_xlfn.CONCAT(Y$1:Y$2,$P30),Table1!$I:$L,2,0) -> 43075 | ... AI30: =VLOOKUP(_xlfn.CONCAT(AI$1:AI$2,$P30),Table1!$I:$L,2,0) -> 7020
A31: TOPCROP | B31: COTTON | C31: obs_n | D31: 211012 | I31: =_xlfn.CONCAT(A31:C31) -> TOPCROPCOTTONobs_n | J31: =D31 -> 211012 | K31: =TEXT(D31,"0")&" ("&TEXT(E31,"0")&")" -> 211012 (0) | L31: =TEXT(D31,"0.00")&" ("&TEXT(E31,"0.00")&")" -> 211012.00 (0.00)
A32: TOPCROP | B32: SUGAR BEETS | C32: obs_n | D32: 18098 | I32: =_xlfn.CONCAT(A32:C32) -> TOPCROPSUGAR BEETSobs_n | J32: =D32 -> 18098 | K32: =TEXT(D32,"0")&" ("&TEXT(E32,"0")&")" -> 18098 (0) | L32: =TEXT(D32,"0.00")&" ("&TEXT(E32,"0.00")&")" -> 18098.00 (0.00)
A33: TOPCROP | B33: CORN | C33: obs_n | D33: 1075064 | I33: =_xlfn.CONCAT(A33:C33) -> TOPCROPCORNobs_n | J33: =D33 -> 1075064 | K33: =TEXT(D33,"0")&" ("&TEXT(E33,"0")&")" -> 1075064 (0) | L33: =TEXT(D33,"0.00")&" ("&TEXT(E33,"0.00")&")" -> 1075064.00 (0.00)
A34: TOPCROP | B34: DRY BEANS | C34: obs_n | D34: 56998 | I34: =_xlfn.CONCAT(A34:C34) -> TOPCROPDRY BEANSobs_n | J34: =D34 -> 56998 | K34: =TEXT(D34,"0")&" ("&TEXT(E34,"0")&")" -> 56998 (0) | L34: =TEXT(D34,"0.00")&" ("&TEXT(E34,"0.00")&")" -> 56998.00 (0.00)
A35: TOPCROP | B35: SORGHUM | C35: obs_n | D35: 167232 | I35: =_xlfn.CONCAT(A35:C35) -> TOPCROPSORGHUMobs_n | J35: =D35 -> 167232 | K35: =TEXT(D35,"0")&" ("&TEXT(E35,"0")&")" -> 167232 (0) | L35: =TEXT(D35,"0.00")&" ("&TEXT(E35,"0.00")&")" -> 167232.00 (0.00)
A36: TOPCROP | B36: DRY PEAS | C36: obs_n | D36: 39338 | I36: =_xlfn.CONCAT(A36:C36) -> TOPCROPDRY PEASobs_n | J36: =D36 -> 39338 | K36: =TEXT(D36,"0")&" ("&TEXT(E36,"0")&")" -> 39338 (0) | L36: =TEXT(D36,"0.00")&" ("&TEXT(E36,"0.00")&")" -> 39338.00 (0.00)
A37: TOPCROP | B37: SUNFLOWERS | C37: obs_n | D37: 55349 | I37: =_xlfn.CONCAT(A37:C37) -> TOPCROPSUNFLOWERSobs_n | J37: =D37 -> 55349 | K37: =TEXT(D37,"0")&" ("&TEXT(E37,"0")&")" -> 55349 (0) | L37: =TEXT(D37,"0.00")&" ("&TEXT(E37,"0.00")&")" -> 55349.00 (0.00)
A38: TOPCROP | B38: SOYBEANS | C38: obs_n | D38: 1017542 | I38: =_xlfn.CONCAT(A38:C38) -> TOPCROPSOYBEANSobs_n | J38: =D38 -> 1017542 | K38: =TEXT(D38,"0")&" ("&TEXT(E38,"0")&")" -> 1017542 (0) | L38: =TEXT(D38,"0.00")&" ("&TEXT(E38,"0.00")&")" -> 1017542.00 (0.00)
A39: TOPCROP | B39: BARLEY | C39: obs_n | D39: 86579 | I39: =_xlfn.CONCAT(A39:C39) -> TOPCROPBARLEYobs_n | J39: =D39 -> 86579 | K39: =TEXT(D39,"0")&" ("&TEXT(E39,"0")&")" -> 86579 (0) | L39: =TEXT(D39,"0.00")&" ("&TEXT(E39,"0.00")&")" -> 86579.00 (0.00)
A40: FCIP | B40: FCIP | C40: coverage_level_percent | D40: 0.72559785 | E40: 0.078965574 | I40: =_xlfn.CONCAT(A40:C40) -> FCIPFCIPcoverage_level_percent | J40: =D40 -> 0.72559785 | K40: =TEXT(D40,"0")&" ("&TEXT(E40,"0")&")" -> 1 (0) | L40: =TEXT(D40,"0.00")&" ("&TEXT(E40,"0.00")&")" -> 0.73 (0.08)
...
